<mujoco model="scout_v2">
    <compiler angle="degree"/>
    <option timestep="0.002"/>

    <!-- Vehicle Geometries -->
    <asset>
        <mesh name="base_link" file="/home/lee/simulation/practice/meshes/base_link.stl"/>
        <mesh name="wheel_type1" file="/home/lee/simulation/practice/meshes/wheel_type1.stl"/>
        <mesh name="wheel_type2" file="/home/lee/simulation/practice/meshes/wheel_type2.stl"/>
    </asset>

    <!-- World body -->
    <worldbody>
        <!-- Base link -->
        <body name="base_link" pos="0 0 0">
            <geom name="base_link_geom" type="mesh" mesh="base_link" pos="0 0 0" euler="90 0 0"/>

            <!-- Inertial properties -->
            <inertial pos="0 0 0" mass="50" diaginertia="2.288641 5.103976 3.431465"/>

            <!-- Scout wheel definitions -->
            <!-- Front Right Wheel -->
            <body name="front_right_wheel" pos="0.249 0.29153 -0.0702">
                <inertial pos="0 0 0" mass="8" diaginertia="0.1171 0.1361 0.1171"/>
                <geom name="front_right_wheel_geom" type="mesh" mesh="wheel_type1" pos="0 0 0" euler="90 0 0"/>
                <geom name="front_right_wheel_collision" type="cylinder" size="0.11653 0.16459" pos="0 0 0" euler="90 0 0"
                      rgba="0 0 0 0" friction="0.9 0.9 0.01" solref="0.02 1" solimp="0.9 0.9 0.01"/>
                <joint name="front_right_wheel_joint" type="hinge" pos="0 0 0" axis="0 1 0"/>
            </body>

            <!-- Front Left Wheel -->
            <body name="front_left_wheel" pos="0.249 -0.29153 -0.0702">
                <inertial pos="0 0 0" mass="8" diaginertia="0.1171 0.1361 0.1171"/>
                <geom name="front_left_wheel_geom" type="mesh" mesh="wheel_type2" pos="0 0 0" euler="90 0 0"/>
                <geom name="front_left_wheel_collision" type="cylinder" size="0.11653 0.16459" pos="0 0 0" euler="90 0 0"
                      rgba="0 0 0 0" friction="0.9 0.9 0.01" solref="0.02 1" solimp="0.9 0.9 0.01"/>
                <joint name="front_left_wheel_joint" type="hinge" pos="0 0 0" axis="0 1 0"/>
            </body>

            <!-- Rear Left Wheel -->
            <body name="rear_left_wheel" pos="-0.249 -0.29153 -0.0702">
                <inertial pos="0 0 0" mass="8" diaginertia="0.1171 0.1361 0.1171"/>
                <geom name="rear_left_wheel_geom" type="mesh" mesh="wheel_type1" pos="0 0 0" euler="90 0 0"/>
                <geom name="rear_left_wheel_collision" type="cylinder" size="0.11653 0.16459" pos="0 0 0" euler="90 0 0"
                      rgba="0 0 0 0" friction="0.9 0.9 0.01" solref="0.02 1" solimp="0.9 0.9 0.01"/>
                <joint name="rear_left_wheel_joint" type="hinge" pos="0 0 0" axis="0 1 0"/>
            </body>

            <!-- Rear Right Wheel -->
            <body name="rear_right_wheel" pos="-0.249 0.29153 -0.0702">
                <inertial pos="0 0 0" mass="8" diaginertia="0.1171 0.1361 0.1171"/>
                <geom name="rear_right_wheel_geom" type="mesh" mesh="wheel_type2" pos="0 0 0" euler="90 0 0"/>
                <geom name="rear_right_wheel_collision" type="cylinder" size="0.11653 0.16459" pos="0 0 0" euler="90 0 0"
                      rgba="0 0 0 0" friction="0.9 0.9 0.01" solref="0.02 1" solimp="0.9 0.9 0.01"/>
                <joint name="rear_right_wheel_joint" type="hinge" pos="0 0 0" axis="0 1 0"/>
            </body>

            <!-- Additional components -->
            <!--<body name="front_mount" pos="0.325 0 0.112701">
                <geom type="box" size="0.1 0.1 0.1" pos="0 0 0"/>
                <joint name="front_mount_joint" type="hinge" pos="0 0 0"/>
            </body>
            <body name="rear_mount" pos="-0.325 0 0.112701">
                <geom type="box" size="0.1 0.1 0.1" pos="0 0 0"/>
                <joint name="rear_mount_joint" type="hinge" pos="0 0 0"/>
            </body>-->
        </body>
    </worldbody>

    <actuator>
        <!-- Define actuators here if needed -->
    </actuator>
</mujoco>
