<mujoco model="perfect">
    <option gravity="5 0 -9.81" />
    <worldbody>
        <light diffuse=".5 .5 .5" pos="0 0 3" dir="0 0 -1"/>
        <geom type="plane" size="5 5 0.1" rgba=".9 .9 .9 1"/>
        <body name="chassis" pos="0 0 0.2" euler="0 90 0">
            <joint type="free"/>
            <geom type="box" size=".05 .2 .5" rgba=".9 .9 0 1"/>
            <body pos="0 0.3 -0.5" euler="90 0 0">
                <joint name="left-wheel" type="hinge" axis="0 0 -1"/>
                <geom type="cylinder" size=".2 0.05" rgba="0 .9 0 1"/>
            </body>
            <body pos="0 -0.3 -0.5" euler="90 0 0">
                <joint name="right-wheel" type="hinge" axis="0 0 -1"/>
                <geom type="cylinder" size=".2 0.05" rgba="0 .9 0 1"/>
            </body>
        </body>
    </worldbody>
    <actuator>
        <velocity name="left-vel" joint="left-wheel" kv="10"/>
        <velocity name="right-vel" joint="right-wheel" kv="10"/>
    </actuator>
</mujoco>
